Workbook

Sheet KODE PROJECT UPDATE SEP 25
A2: NO | B2: NAMA PELANGGAN | C2: SEGMENTASI | D2: NAMA PROJECT | E2: KODE PROJECT | F2: KETERANGAN
A3: 1 | B3: PT GAGAS ENERGI INDONESIA | C3: BUSINESS SOLUTION | D3: PENGADAAN CCTV SPBG LAMPUNG | E3: BS-001
A4: 2 | B4: PT WIDAR MANDRIPA NUSANTARA | C4: BUSINESS SOLUTION | D4: ABSEN ONLINE | E4: BS-002
A5: 3 | B5: PT PERTAMINA (PERSERO) | C5: BUSINESS SOLUTION | D5: PENYEDIAAN JASA LAYANAN KLASIFIKASI KEAMANAN INFORMASI | E5: BS-003
A6: 4 | B6: PT PERUSAHAAN GAS NEGARA | C6: BUSINESS SOLUTION | D6: PEKERJAAN PENGADAAN DAN PEMASANGAN PRESSURE MONITORING DEVICE PLN TARAHAN LAMPUNG | E6: BS-004 | F6: IOGM
A7: 5 | B7: SAKA INDONESIA PANGKAH LTD | C7: BUSINESS SOLUTION | D7: SMART PRESENCE SUBSCRIPTON | E7: BS-005
A8: 6 | B8: PT GAGAS ENERGI INDONESIA | C8: BUSINESS SOLUTION | D8: PENGADAAN CCTV SPBG PONDOK UNGU | E8: BS-006
A9: 7 | B9: PT ALGAS | C9: BUSINESS SOLUTION | D9: PROJECT INSTAL EVC VEMMTEC V5 SYSTEM BILLING AVE PGNCOM | E9: BS-007
A10: 8 | B10: PT PERTAMINA (PERSERO) | C10: BUSINESS SOLUTION | D10: PERPANJANGAN SUPPORT MAIL SECURITY GATEAWAY PERTAMINA PERSERO | E10: BS-008
A11: 9 | B11: PT PERUSAHAAN GAS NEGARA | C11: BUSINESS SOLUTION | D11: LAPTOP OWNERSHIP PROGRAM 2019-2020 | E11: BS-009 | F11: ICT
A12: 10 | B12: PT TELEMEDIA DINAMIKA SARANA | C12: BUSINESS SOLUTION | D12: LAPTOP OWNERSHIP GASNET | E12: BS-010
A13: 11 | B13: PT PERUSAHAAN GAS NEGARA | C13: BUSINESS SOLUTION | D13: SISTEM RESTRUKTURISASI DAN PENGENDALIAN PEMAKAIAN GAS REVAS-2023 | E13: BS-011 | F13: REVAS
A14: 12 | B14: PT PERUSAHAAN GAS NEGARA | C14: BUSINESS SOLUTION | D14: PENGADAAN JASA PEMELIHARAAN PREPAID MANAGEMENT SYSTEM DAN LAYANAN PENDUKUNG REVENUE ASSURANCE | E14: BS-012 | F14: REVAS
A15: 13 | B15: PT PERUSAHAAN GAS NEGARA | C15: BUSINESS SOLUTION | D15: DASHBOARD MOBILE APPS (DASHBOARD PSAIMS) | E15: BS-013 | F15: HSSE
A16: 14 | B16: PT PERUSAHAAN GAS NEGARA | C16: BUSINESS SOLUTION | D16: MOBILE APPS DEVELOPMENT (HSSE PASSPORT) | E16: BS-014 | F16: HSSE
A17: 15 | B17: PT PERUSAHAAN GAS NEGARA | C17: BUSINESS SOLUTION | D17: RELOKASI PMD PAYA PASIR KE DELI SERDANG | E17: BS-015 | F17: IOGM
A18: 16 | B18: PT KILANG PERTAMINA INTERNASIONAL | C18: BUSINESS SOLUTION | D18: JASA PENDAMPINGAN SERTIFIKASI ISO 27001:2022 | E18: BS-016
A19: 17 | B19: PT PERUSAHAAN GAS NEGARA | C19: BUSINESS SOLUTION | D19: KELTON | E19: BS-017
A20: 18 | B20: PT PERUSAHAAN GAS NEGARA | C20: BUSINESS SOLUTION | D20: PMD | E20: BS-018
A21: 19 | B21: PT NUSANTARA REGAS | C21: BUSINESS SOLUTION | D21: Jasa Event IT Security Jan 2024 - Des 2025 | E21: BS-019
A22: 20 | B22: PERUSAHAAN GAS NEGARA - IOGM | C22: BUSINESS SOLUTION | D22: Pekerjaan Pengadaan dan Pemasangan Pressure Monitoring Device Batang Tahun 2025 | E22: BS-020 | F22: IOGM
A23: 21 | B23: PT PERTAMINA (PERSERO) | C23: BUSINESS SOLUTION | D23: Penyediaan Lisensi OriginPro Pertamina Tahun 2025 | E23: BS-021
A24: 22 | B24: PT PERUSAHAAN GAS NEGARA | C24: BUSINESS SOLUTION | D24: Pengembangan Aplikasi SHARE Modul SIM TJSL | E24: BS-022 | F24: CSR
A25: 23 | B25: PT PERTAMINA PATRA NIAGA | C25: BUSINESS SOLUTION | D25: Pekerjaan Maintenance CCTV & Infrastruktur PPN MOR1 FT Labuhan Deli | E25: BS-023
A26: 24 | B26: PT TRANSPORTASI GAS INDONESIA | C26: BUSINESS SOLUTION | D26: Pengadaan Firewall Amandemen Perjanjian Pengadaan Link Metro Ethemet Dan Colocation Data Center Utama PT Transportasi Gas Indonesia | E26: BS-024
A27: 25 | B27: PT SUPREME ENERGY RANTAU DEDAP | C27: BUSINESS SOLUTION | D27: Pekerjaan System ATS ECM Suite 25 di PT Supreme Energy Rantau Dedap (SERD) | E27: BS-025
A28: 26 | B28: PT SUPREME ENERGY MUARA LABOH | C28: BUSINESS SOLUTION | D28: Pekerjaan System ATS ECM Suite 25 di PT Supreme Energy Muara Laboh (SEML) | E28: BS-026
A29: 27 | C29: BUSINESS SOLUTION | D29: Pekerjaan BER Test DC Kemendagri | E29: BS-027
A30: 28 | C30: BUSINESS SOLUTION | D30: Sewa BERT Test Kemendagri | E30: BS-028
A31: 29 | B31: PT KILANG PERTAMINA INTERNASIONAL | C31: BUSINESS SOLUTION | D31: Pengadaan Jasa Pendampingan Surveillance Sertifikasi ISO/IEC 27001:2022 DI PT KPI | E31: BS-029
A32: 30 | B32: PT KILANG PERTAMINA INTERNASIONAL | C32: BUSINESS SOLUTION | D32: Pengadaan Jasa Implementasi Data Governance Di PT Kilang Pertamina Internasional | E32: BS-030
A34: 1 | B34: PT PERUSAHAAN GAS NEGARA | C34: MANAGED SERVICE | D34: JASA PEMELIHARAAN DAN PENGEMBANGAN PREPAID MANAGEMENT SYSTEM - 2023 | E34: MS-001 | F34: REVAS
A35: 2 | B35: PT PERUSAHAAN GAS NEGARA | C35: MANAGED SERVICE | D35: AMD JASA PEMELIHARAAN DAN PENGEMBANGAN PREPAID MANAGEMENT SYSTEM 2023 | E35: MS-002 | F35: REVAS
A36: 3 | B36: PT PERUSAHAAN GAS NEGARA | C36: MANAGED SERVICE | D36: PEKERJAAN JASA OPERASI DAN PEMELIHARAAN GAS MANAGEMEN SISTEM | E36: MS-003 | F36: IOGM
A37: 4 | B37: PT PERUSAHAAN GAS NEGARA | C37: MANAGED SERVICE | D37: PENYEDIAAN LAYANAN SISTEM RADIO KOMUNIKASI | E37: MS-004 | F37: IOGM
A38: 5 | B38: PT PGAS SOLUTION | C38: MANAGED SERVICE | D38: COLOCATION BACKUP DATA CENTER | E38: MS-005
A39: 6 | B39: PT PGAS SOLUTION | C39: MANAGED SERVICE | D39: SEWA LAPTOP PGASOL 3 (WO 2) | E39: MS-006
A40: 7 | B40: PT PGAS SOLUTION | C40: MANAGED SERVICE | D40: SEWA LAPTOP PGASOL 4 (WO 3) | E40: MS-007
A41: 8 | B41: PT PGAS SOLUTION | C41: MANAGED SERVICE | D41: SEWA LAPTOP PGASOL 5 (WO 4) | E41: MS-008
A42: 9 | B42: PT PGAS SOLUTION | C42: MANAGED SERVICE | D42: PENYEDIAAN LAYANAN CLOUD VIRTUAL PRIVATE SERVER (KONTRAK PAYUNG) | E42: MS-009
...

Sheet KODE PROJECT BARU
A2: LIST PEKERJAAN ONGOING PER 1 JUNI 2026
A4: Group ID | B4: Project ID Lama | C4: Project ID Baru | D4: Project_client | E4: Project Name | G4: GRUP | H4: KODE | I4: KODE | K4: Nomor | L4: CLIENT2 | M4: INITIAL | N4: GRUP
G5: HOLDING | H5: G1 | I5: G1 | K5: 1 | L5: PT Perusahaan Gas Negara | M5: PGN | N5: G2
B6: BS-019 | C6: BS-019 | D6: NRG | E6: Jasa Event IT Security Januari 2024 - Desember 2025 | G6: SHG | H6: G2 | I6: G2 | K6: 2 | L6: PT PGN LNG Indonesia | M6: PLI | N6: G3
B7: MS-020 | C7: MS-020 | D7: NRG | E7: Layanan Radio Komunikasi-Trunking 24 Bulan | G7: PGN GROUP | H7: G3 | I7: G3 | K7: 3 | L7: PT Pertamina Gas | M7: PTG | N7: G3
B8: MS-062 | C8: MS-062 | D8: NRG | E8: Pekerjaan Jasa Pengadaan Event IT Security PT Nusantara Regas | G8: PERTAMINA GROUP | H8: G4 | I8: G4 | K8: 4 | L8: PT Pertamina Persero | M8: PTM | N8: G1
B9: MS-077 | C9: MS-077 | D9: PGN | E9: Enhancement Aplikasi System Integrasi Datamart & Tools Monitoring Dashboard Management Kinerja Niaga | G9: NON PERTAMINA | H9: G5 | I9: G5 | K9: 5 | L9: PT Nusantara Regas | M9: NRG | N9: G3
B10: BS-023 | C10: BS-023 | D10: PPN | E10: Pekerjaan Maintenance CCTV & Infrastruktur PPN MOR1 FT Labuhan Deli | K10: 6 | L10: PT Saka Energi Indonesia | M10: SAKA | N10: G3
B11: BS-024 | C11: BS-024 | D11: TGI | E11: Pengadaan Firewall Amandemen Perjanjian Pengadaan Link Metro Ethemet Dan Colocation Data Center Utama PT Transportasi Gas Indonesia | K11: 7 | L11: PT Pertamina Energi Terminal | M11: PET | N11: G4
B12: BS-025 | C12: BS-025 | D12: SERD | E12: Pekerjaan System ATS ECM Suite 25 di PT Supreme Energy Rantau Dedap (SERD) | K12: 8 | L12: PT Pelita Air Service | M12: PAS | N12: G5
B13: BS-026 | C13: BS-026 | D13: SEML | E13: Pekerjaan System ATS ECM Suite 25 di PT Supreme Energy Muara Laboh (SEML) | K13: 9 | L13: PT PGAS Solution | M13: PSOL | N13: G3
B14: BS-027 | C14: BS-027 | E14: Pekerjaan BER Test DC Kemendagri | K14: 10 | L14: PT Pertamina Hulu Energi | M14: PHE | N14: G4
B15: BS-028 | C15: BS-028 | E15: Sewa BERT Test Kemendagri | K15: 11 | L15: PT Kalimantan Jawa gas | M15: KJG | N15: G3
B16: BS-029 | C16: BS-029 | D16: KPI | E16: Pengadaan Jasa Pendampingan Surveillance Sertifikasi ISO/IEC 27001:2022 DI PT KPI | K16: 12 | L16: PT Pertamina International Shipping | M16: PIS | N16: G4
K17: 13 | L17: PT Gagas Energi Indonesia | M17: GGS | N17: G3
C18: PS-000-00 | D18: PLI | E18: Pengadaan CCTV PT PGN LNG | K18: 14 | L18: PT Widar Mandripa Nusantara | M18: WDR | N18: G3
A19: G3 | B19: MS-026 | C19: PS-001-00 | D19: PTG | E19: Manage Service Layanan Printer, Scanner, Multimedia dan UPS System di PT Pertamina Gas | K19: 15 | L19: PT Pertamina Geothermal Energy | M19: PGE | N19: G4
A20: G4 | B20: MS-081 | C20: PS-002-00 | D20: PPN | E20: Pekerjaan Sewa Router Untuk Layanan Dual Link SPBU | K20: 16 | L20: PT Kilang Pertamina Internasional | M20: KPI | N20: G4
A21: G4 | B21: MS-016 | C21: PS-003-00 | D21: WDR | E21: Pengadaan Sewa Aplikasi Absensi Online (Bimasakti) PT Widar Mandripa Nusantara | K21: 17 | L21: PT Pertamina Patra Niaga | M21: PPN | N21: G4
A22: G1 | B22: MS-031 | C22: PS-004-00 | D22: PTM | E22: Pengelolaan & Pengembangan Servicedesk Shared Services Pertamina | K22: 18 | L22: PT Nippon Shokubai Indonesia | M22: NSI | N22: G5
A23: G3 | B23: MS-074 | C23: PS-005-00 | D23: KJG | E23: Pengadaan Jasa penyediaan Perangkat Sistem Informasi | K23: 19 | L23: PT Pertagas Niaga | M23: PTGN | N23: G3
A24: G3 | B24: MS-088 | C24: PS-006-00 | D24: PSOL | E24: Implementasi Vulnerability Assessment & Penetration Test (VAPT) dan Technical Service Cyber Security | K24: 20 | L24: Yayasan Kesehatan Pertamina | M24: YKP | N24: G4
A25: G2 | B25: MS-075 | C25: PS-007-00 | D25: PGN | E25: Pekerjaan Penyediaan Layanan Sewa Server YKPP PGN | K25: 21 | L25: PT Pekerbunan Nusantara I
A26: G2 | B26: MS-100 | C26: PS-008-00 | D26: PGN | E26: Jasa Teknikal Asistensi Sistem Manajemen Informasi Legal (SMILE) | K26: 22 | L26: PT Pekerbunan Nusantara III
A27: G3 | B27: MS-076 | C27: PS-009-00 | D27: NRG | E27: Jasa Implementasi Security Information Event Management (SIEM) dan Security Operation Center (SOC) | K27: 23 | L27: PT Pekerbunan Nusantara IV
A28: G1 | C28: PS-010-00 | D28: PTM | E28: Penyediaan Jasa Dukungan Operasional Fungsi Shared Services ICT Tahun | K28: 24 | L28: PT Sinergi Gula Nusantara
A29: G2 | B29: MS-098 | C29: PS-011-00 | D29: PGN | E29: Penyediaan Lisensi Piranti Lunak dan Annual Technical Support | K29: 25 | L29: PT Riset Perkebunan Nusantara
A30: G1 | C30: PS-012-00 | D30: PTM | E30: Pengadaan Jasa Penyediaan Endpoint Security | K30: 26 | L30: PT LPP Agro Nusantara
A31: G1 | B31: MS-086 | C31: PS-013-00 | D31: PTM | E31: Pengadaan Sewa Perangkat Storage san NTP Server Pertamina | K31: 27 | L31: PT Kharisma Pemasaran Bersama Nusantara
A32: G1 | B32: MS-040 | C32: PS-014-00 | D32: PTM | E32: Penyediaan Jasa Layanan Offline Backup AWS Phase 1 | K32: 28 | L32: PT Industri Karet Nusantara
A33: G1 | B33: MS-087 | C33: PS-015-00 | D33: PTM | E33: Tindak Lanjut Pekerjaan Jasa Managed Service Security Assessment (MSSA) | K33: 29 | L33: PT Sri Pamela Medika Nusantara
A34: G2 | B34: MS-012 | C34: PS-016-00 | D34: PGN | E34: Jasa Managed Service Pengelolaan Layanan Pelanggan Melalui Contact Center | K34: 30 | L34: PT Kawasan Industri Nusantara
A35: G2 | B35: MS-061 | C35: PS-017-00 | D35: PGN | E35: Jasa Penyediaan Perangkat Multimedia dan Peralatan Pendukung Ruang Integrated Monitoring Center (IMOC) | K35: 31 | L35: PT Bio Industri Nusantara
A36: G2 | C36: PS-018-00 | D36: PGN | E36: Managed Service Aplication Integration Solutions (MSAIS) | K36: 32 | L36: PT Supreme Energi Muara Laboh
A37: G2 | C37: PS-018-01 | D37: PGN | E37: Managed Service Aplication Integration Solutions (MSAIS): Jasa enhancement E-SMS 2026 | K37: 33 | L37: PT Supreme Energi Rantau Dedap
A38: G2 | C38: PS-018-02 | D38: PGN | E38: Pekerjaan Enhancement 16 KB Page File (Android), Multifactor Authentification (MFA) (Android & IOS) Serta Implementasi Progressive Web App (PWA)
A39: G2 | C39: PS-018-03 | D39: PGN | E39: Pekerjaan Pengelolaan & Dukungan Aplikasi Kepelangganan PGN Tahun 2026
A40: G2 | B40: MS-053 | C40: PS-019-00 | D40: PGN | E40: Managed Service Backup Management (Vinchin)
A41: G2 | B41: MS-049 | C41: PS-020-00 | D41: PGN | E41: Managed Service Cyber Security (MSCS)
A42: G2 | B42: MS-048 | C42: PS-021-00 | D42: PGN | E42: Managed Service OT Security (MSOT)
...

Sheet PROGNOSA 2026
B2: No | C2: Kode Project | D2: Nama Pekerjaan | E2: Aktivity | F2: Satuan Kerja | G2: PIC | H2: Prognosa Biaya | I2: Periode | J2: Partner | K2: Keterangan | L2: Tahun
B3: 0 | C3: PS-024-00 | D3: =_xlfn.XLOOKUP(C3,'KODE PROJECT BARU'!$C$5:$C$98,'KODE PROJECT BARU'!$E$5:$E$98,"N/A",0,1) -> #NAME? | E3: Biaya Pekerja | F3: DMO | G3: Fikar | H3: 1000 | I3: AGUSTUS | J3: PT Personel Alih Daya
C6: PS-019-00 | D6: =_xlfn.XLOOKUP(C6,'KODE PROJECT BARU'!$C$5:$C$98,'KODE PROJECT BARU'!$E$5:$E$98,"N/A",0,1) -> #NAME? | E6: BIAYA BUFFER | F6: DMO | G6: CHYNTIA | H6: 3117000 | I6: JULI | J6: =UPPER(J3) -> PT PERSONEL ALIH DAYA | L6: 2026
C7: PS-019-00 | D7: =_xlfn.XLOOKUP(C7,'KODE PROJECT BARU'!$C$5:$C$98,'KODE PROJECT BARU'!$E$5:$E$98,"N/A",0,1) -> #NAME? | E7: BIAYA BUFFER | F7: DMO | G7: CHYNTIA | H7: 3117000 | I7: OKTOBER | J7: PT PERSONEL ALIH DAYA | L7: 2026
C8: PS-019-00 | D8: =_xlfn.XLOOKUP(C8,'KODE PROJECT BARU'!$C$5:$C$98,'KODE PROJECT BARU'!$E$5:$E$98,"N/A",0,1) -> #NAME? | E8: BIAYA BUFFER | F8: DMO | G8: CHYNTIA | H8: 3117000 | I8: DESEMBER | J8: PT PERSONEL ALIH DAYA | L8: 2026
C9: PS-019-00 | D9: =_xlfn.XLOOKUP(C9,'KODE PROJECT BARU'!$C$5:$C$98,'KODE PROJECT BARU'!$E$5:$E$98,"N/A",0,1) -> #NAME? | E9: UPAH | F9: DMO | G9: CHYNTIA | H9: 27622955 | I9: JULI | J9: PT PERSONEL ALIH DAYA | L9: 2026
C10: PS-019-00 | D10: =_xlfn.XLOOKUP(C10,'KODE PROJECT BARU'!$C$5:$C$98,'KODE PROJECT BARU'!$E$5:$E$98,"N/A",0,1) -> #NAME? | E10: UPAH | F10: DMO | G10: CHYNTIA | H10: 27622955 | I10: AGUSTUS | J10: PT PERSONEL ALIH DAYA | L10: 2026
C11: PS-019-00 | D11: =_xlfn.XLOOKUP(C11,'KODE PROJECT BARU'!$C$5:$C$98,'KODE PROJECT BARU'!$E$5:$E$98,"N/A",0,1) -> #NAME? | E11: UPAH | F11: DMO | G11: CHYNTIA | H11: 27622955 | I11: SEPTEMBER | J11: PT PERSONEL ALIH DAYA | L11: 2026
C12: PS-019-00 | D12: =_xlfn.XLOOKUP(C12,'KODE PROJECT BARU'!$C$5:$C$98,'KODE PROJECT BARU'!$E$5:$E$98,"N/A",0,1) -> #NAME? | E12: UPAH | F12: DMO | G12: CHYNTIA | H12: 27622955 | I12: OKTOBER | J12: PT PERSONEL ALIH DAYA | L12: 2026
C13: PS-019-00 | D13: =_xlfn.XLOOKUP(C13,'KODE PROJECT BARU'!$C$5:$C$98,'KODE PROJECT BARU'!$E$5:$E$98,"N/A",0,1) -> #NAME? | E13: UPAH | F13: DMO | G13: CHYNTIA | H13: 27622955 | I13: NOVEMBER | J13: PT PERSONEL ALIH DAYA | L13: 2026
C14: PS-019-00 | D14: =_xlfn.XLOOKUP(C14,'KODE PROJECT BARU'!$C$5:$C$98,'KODE PROJECT BARU'!$E$5:$E$98,"N/A",0,1) -> #NAME? | E14: UPAH | F14: DMO | G14: CHYNTIA | H14: 27622955 | I14: DESEMBER | J14: PT PERSONEL ALIH DAYA | L14: 2026
C15: PS-019-00 | D15: =_xlfn.XLOOKUP(C15,'KODE PROJECT BARU'!$C$5:$C$98,'KODE PROJECT BARU'!$E$5:$E$98,"N/A",0,1) -> #NAME? | E15: PIKET NATARU | F15: DMO | G15: CHYNTIA | H15: 2168861 | I15: DESEMBER | J15: PT PERSONEL ALIH DAYA | L15: 2026
C16: PS-019-00 | D16: =_xlfn.XLOOKUP(C16,'KODE PROJECT BARU'!$C$5:$C$98,'KODE PROJECT BARU'!$E$5:$E$98,"N/A",0,1) -> #NAME? | E16: SPPD | F16: DMO | G16: CHYNTIA | H16: 12149698 | I16: DESEMBER | J16: PT PERSONEL ALIH DAYA | L16: 2026
C17: PS-019-00 | D17: =_xlfn.XLOOKUP(C17,'KODE PROJECT BARU'!$C$5:$C$98,'KODE PROJECT BARU'!$E$5:$E$98,"N/A",0,1) -> #NAME? | E17: TRAINING | F17: DMO | G17: CHYNTIA | H17: 4119200 | I17: DESEMBER | J17: PT PERSONEL ALIH DAYA | L17: 2026
C18: PS-019-00 | D18: =_xlfn.XLOOKUP(C18,'KODE PROJECT BARU'!$C$5:$C$98,'KODE PROJECT BARU'!$E$5:$E$98,"N/A",0,1) -> #NAME? | E18: WORKSHOP | F18: DMO | G18: CHYNTIA | H18: 248988231 | I18: DESEMBER | J18: PT PERSONEL ALIH DAYA | L18: 2026
... C21: PS-040-00 | D21: =_xlfn.XLOOKUP(C21,'KODE PROJECT BARU'!$C$5:$C$98,'KODE PROJECT BARU'!$E$5:$E$98,"N/A",0,1) -> #NAME? | E21: VAPT 2 | F21: OSM | G21: RIKI | H21: 27500000 | I21: DESEMBER | J21: PT. CYNNEX INTEGRASI SOLUSI | L21: 2026
C22: PS-040-00 | D22: =_xlfn.XLOOKUP(C22,'KODE PROJECT BARU'!$C$5:$C$98,'KODE PROJECT BARU'!$E$5:$E$98,"N/A",0,1) -> #NAME? | E22: CLOUD VPS | F22: OSM | G22: RIKI | H22: =360000000/3 -> 120000000 | I22: DESEMBER | J22: PT DATACOMM DIANGRAHA | L22: 2026
C23: PS-040-00 | D23: =_xlfn.XLOOKUP(C23,'KODE PROJECT BARU'!$C$5:$C$98,'KODE PROJECT BARU'!$E$5:$E$98,"N/A",0,1) -> #NAME? | E23: CLOUD VPS(AMD) | F23: OSM | G23: RIKI | H23: 18000000 | I23: DESEMBER | L23: 2026
C24: PS-030-00 | D24: =_xlfn.XLOOKUP(C24,'KODE PROJECT BARU'!$C$5:$C$98,'KODE PROJECT BARU'!$E$5:$E$98,"N/A",0,1) -> #NAME? | E24: MRC MEI | F24: OSM | G24: RIKI | H24: 367250000 | I24: JULI | J24: PT. BERCA HARDAYAPRAKARSA | L24: 2026
C25: PS-030-00 | D25: =_xlfn.XLOOKUP(C25,'KODE PROJECT BARU'!$C$5:$C$98,'KODE PROJECT BARU'!$E$5:$E$98,"N/A",0,1) -> #NAME? | E25: MRC JUNI | F25: OSM | G25: RIKI | H25: 367250000 | I25: AGUSTUS | L25: 2026
C26: PS-030-00 | D26: =_xlfn.XLOOKUP(C26,'KODE PROJECT BARU'!$C$5:$C$98,'KODE PROJECT BARU'!$E$5:$E$98,"N/A",0,1) -> #NAME? | E26: MRC JULI | F26: OSM | G26: RIKI | H26: 367250000 | I26: SEPTEMBER | L26: 2026
C27: PS-030-00 | D27: =_xlfn.XLOOKUP(C27,'KODE PROJECT BARU'!$C$5:$C$98,'KODE PROJECT BARU'!$E$5:$E$98,"N/A",0,1) -> #NAME? | E27: MRC AGUSTUS | F27: OSM | G27: RIKI | H27: 367250000 | I27: OKTOBER | L27: 2026
C28: PS-030-00 | D28: =_xlfn.XLOOKUP(C28,'KODE PROJECT BARU'!$C$5:$C$98,'KODE PROJECT BARU'!$E$5:$E$98,"N/A",0,1) -> #NAME? | E28: MRC SEPTEMBER | F28: OSM | G28: RIKI | H28: 367250000 | I28: NOVEMBER | L28: 2026
C29: PS-030-00 | D29: =_xlfn.XLOOKUP(C29,'KODE PROJECT BARU'!$C$5:$C$98,'KODE PROJECT BARU'!$E$5:$E$98,"N/A",0,1) -> #NAME? | E29: MRC OKTOBER | F29: OSM | G29: RIKI | H29: 367250000 | I29: DESEMBER | L29: 2026
C30: PS-030-00 | D30: =_xlfn.XLOOKUP(C30,'KODE PROJECT BARU'!$C$5:$C$98,'KODE PROJECT BARU'!$E$5:$E$98,"N/A",0,1) -> #NAME? | E30: MRC NOVEMBER | F30: OSM | G30: RIKI | H30: 367250000 | I30: DESEMBER | L30: 2026
C31: PS-030-00 | D31: =_xlfn.XLOOKUP(C31,'KODE PROJECT BARU'!$C$5:$C$98,'KODE PROJECT BARU'!$E$5:$E$98,"N/A",0,1) -> #NAME? | E31: MRC DESEMBER | F31: OSM | G31: RIKI | H31: 367250000 | I31: DESEMBER | L31: 2026
C32: PS-030-00 | D32: =_xlfn.XLOOKUP(C32,'KODE PROJECT BARU'!$C$5:$C$98,'KODE PROJECT BARU'!$E$5:$E$98,"N/A",0,1) -> #NAME? | E32: AMD JASA INSTALASI RAM | F32: OSM | G32: RIKI | H32: 57000000 | I32: JULI | L32: 2026
C33: PS-030-00 | D33: =_xlfn.XLOOKUP(C33,'KODE PROJECT BARU'!$C$5:$C$98,'KODE PROJECT BARU'!$E$5:$E$98,"N/A",0,1) -> #NAME? | E33: ADD POWER DCI 3KVA | F33: OSM | G33: RIKI | H33: 216000000 | I33: DESEMBER | J33: PT. DCI | K33: SO 626 | L33: 2026
C34: PS-018-00 | D34: =_xlfn.XLOOKUP(C34,'KODE PROJECT BARU'!$C$5:$C$98,'KODE PROJECT BARU'!$E$5:$E$98,"N/A",0,1) -> #NAME? | E34: Biaya Pekerja | F34: DMO | G34: CHYNTIA | H34: =9959571+28053000+338125868 -> 376138439 | I34: JULI | J34: PT PERSONEL ALIH DAYA | L34: 2026
C35: PS-018-00 | D35: =_xlfn.XLOOKUP(C35,'KODE PROJECT BARU'!$C$5:$C$98,'KODE PROJECT BARU'!$E$5:$E$98,"N/A",0,1) -> #NAME? | E35: Biaya Pekerja | F35: DMO | G35: CHYNTIA | H35: =9959571+338125868 -> 348085439 | I35: AGUSTUS | J35: PT PERSONEL ALIH DAYA | L35: 2026
C36: PS-018-00 | D36: =_xlfn.XLOOKUP(C36,'KODE PROJECT BARU'!$C$5:$C$98,'KODE PROJECT BARU'!$E$5:$E$98,"N/A",0,1) -> #NAME? | E36: Biaya Pekerja | F36: DMO | G36: CHYNTIA | H36: =9959571+338125868 -> 348085439 | I36: SEPTEMBER | J36: PT PERSONEL ALIH DAYA | L36: 2026
C37: PS-018-00 | D37: =_xlfn.XLOOKUP(C37,'KODE PROJECT BARU'!$C$5:$C$98,'KODE PROJECT BARU'!$E$5:$E$98,"N/A",0,1) -> #NAME? | E37: Biaya Pekerja | F37: DMO | G37: CHYNTIA | H37: =9959571+28053000+338125868 -> 376138439 | I37: OKTOBER | J37: PT PERSONEL ALIH DAYA | L37: 2026
C38: PS-018-00 | D38: =_xlfn.XLOOKUP(C38,'KODE PROJECT BARU'!$C$5:$C$98,'KODE PROJECT BARU'!$E$5:$E$98,"N/A",0,1) -> #NAME? | E38: Biaya Pekerja | F38: DMO | G38: CHYNTIA | H38: =9959571+338125868 -> 348085439 | I38: NOVEMBER | J38: PT PERSONEL ALIH DAYA | L38: 2026
C39: PS-018-00 | D39: =_xlfn.XLOOKUP(C39,'KODE PROJECT BARU'!$C$5:$C$98,'KODE PROJECT BARU'!$E$5:$E$98,"N/A",0,1) -> #NAME? | E39: Biaya Pekerja | F39: DMO | G39: CHYNTIA | H39: =9959571+28053000+338125868+5452613+31923800+295739679+255116431+37579894 -> 1001950856 | I39: DESEMBER | J39: PT PERSONEL ALIH DAYA | L39: 2026
C54: PS-023-00 | D54: =_xlfn.XLOOKUP(C54,'KODE PROJECT BARU'!$C$5:$C$98,'KODE PROJECT BARU'!$E$5:$E$98,"N/A",0,1) -> #NAME? | E54: PARKIR | F54: DMO | G54: CHYNTIA | H54: 822888 | I54: JULI | J54: PT PERSONEL ALIH DAYA | L54: 2026
C55: PS-023-00 | D55: =_xlfn.XLOOKUP(C55,'KODE PROJECT BARU'!$C$5:$C$98,'KODE PROJECT BARU'!$E$5:$E$98,"N/A",0,1) -> #NAME? | E55: PARKIR | F55: DMO | G55: CHYNTIA | H55: 822888 | I55: AGUSTUS | J55: PT PERSONEL ALIH DAYA | L55: 2026
C56: PS-023-00 | D56: =_xlfn.XLOOKUP(C56,'KODE PROJECT BARU'!$C$5:$C$98,'KODE PROJECT BARU'!$E$5:$E$98,"N/A",0,1) -> #NAME? | E56: PARKIR | F56: DMO | G56: CHYNTIA | H56: 822888 | I56: SEPTEMBER | J56: PT PERSONEL ALIH DAYA | L56: 2026
C57: PS-023-00 | D57: =_xlfn.XLOOKUP(C57,'KODE PROJECT BARU'!$C$5:$C$98,'KODE PROJECT BARU'!$E$5:$E$98,"N/A",0,1) -> #NAME? | E57: PARKIR | F57: DMO | G57: CHYNTIA | H57: 822888 | I57: OKTOBER | J57: PT PERSONEL ALIH DAYA | L57: 2026
C58: PS-023-00 | D58: =_xlfn.XLOOKUP(C58,'KODE PROJECT BARU'!$C$5:$C$98,'KODE PROJECT BARU'!$E$5:$E$98,"N/A",0,1) -> #NAME? | E58: PARKIR | F58: DMO | G58: CHYNTIA | H58: 822888 | I58: NOVEMBER | J58: PT PERSONEL ALIH DAYA | L58: 2026
C59: PS-023-00 | D59: =_xlfn.XLOOKUP(C59,'KODE PROJECT BARU'!$C$5:$C$98,'KODE PROJECT BARU'!$E$5:$E$98,"N/A",0,1) -> #NAME? | E59: PARKIR | F59: DMO | G59: CHYNTIA | H59: 822888 | I59: DESEMBER | J59: PT PERSONEL ALIH DAYA | L59: 2026
...

Sheet APLIKASI
A2: No | B2: Kontrak Induk | C2: Kontrak Turunan | D2: Client | E2: Sales | F2: Area | G2: End of contract | H2: Nilai
A3: 1 | B3: kontrak tunggal | C3: Pekerjaan Penyediaan Aplikasi Performance And Competency Management Competency Management | D3: PT Gagas Energi Indonesia | E3: Hona | F3: HO | G3: 46023
A4: 2 | B4: kontrak tunggal | C4: Pekerjaan Jasa Developing Dashboard PSAIMS dan HSSE Forntliner System | D4: PT Perusahaan Gas Negara | E4: Kelvin | F4: HO | G4: 46022
A5: 3 | B5: kontrak tunggal | C5: Tindak Lanjut Pekerjaan Pengadaan Jasa Tekninal Asistensi Sistem Management Informasi Legal | D5: PT Perusahaan Gas Negara | E5: Kelvin | F5: HO | G5: 46288
A6: 4 | B6: kontrak tunggal | C6: Pengadaan Jasa Manage Service E-KYC | D6: PT Perusahaan Gas Negara | E6: Junita | F6: HO | G6: 46387
A7: 5 | B7: kontrak tunggal | C7: Layanan Customer Relationship Management Billing Retail (end mei 2024) | D7: PT Telemedia Dinamika Sarana | E7: Ega | F7: HO | G7: 45443
A8: 6 | B8: kontrak tunggal | C8: Pengadaan Pembangunan SIPGAS EM Fungsi Monitoring Komunikasi CRM Tahun 2024 | D8: PT Perusahaan Gas Negara | E8: Kelvin | F8: HO | G8: 45657
A9: 7 | B9: kontrak tunggal | C9: Perpanjangan Layanan Delivery Pekerjaan Pengadaan Sewa Aplikasi Point of Sales untuk Pemberdayaan Aset 2026 | D9: PT Perusahaan Gas Negara | E9: Nisa | F9: HO | G9: 46022
A10: 8 | B10: kontrak tunggal | C10: Managed Service Aplikasi Pengelolaan Piutang (Modul Restrukturisasi Piutang & Pengendalian {Pemakaian Gas) | D10: PT Perusahaan Gas Negara | E10: Junita | F10: HO | G10: 46022
A11: 9 | B11: kontrak tunggal | C11: Delivery Jasa Pemeliharaan APlikasi HSSE Online System and Indicator Performance Center | D11: PT Perusahaan Gas Negara | E11: Kelvin | F11: HO | G11: 46022
A12: 10 | C12: Smart meter | D12: PT Perusahaan Gas Negara | E12: Erdika | F12: HO
A13: 11 | B13: kontrak tunggal | C13: Geospatial Update Licensing Information System | D13: PT Perusahaan Gas Negara | E13: Mumtaz | F13: RO Bekasi | G13: 46022
A14: 12 | B14: kontrak tunggal | C14: Jasa Pembuatan Sistem Data Kinerja PGN SOR III | D14: PT Perusahaan Gas Negara | E14: Rosiana | F14: RO Jabatim | G14: 45994
A15: 13 | B15: kontrak tunggal | C15: Pengembangan dan Peningkatan Kapabilitas Aplikasi ENERGY (Enterprise Revenue Generation System) | D15: PT Perusahaan Gas Negara | E15: Alifa | F15: RO Jakarta | G15: 46022
A16: 14 | B16: LPASI 2025 | C16: LPASI : Pembuatan Dashboard ELO Procurement | D16: PT Perusahaan Gas Negara | E16: Alifa | F16: RO Jakarta | G16: 46022
A17: 15 | B17: LPASI 2025 | C17: LPASI : Implementasi DAMARA & ELO ECM Suite | D17: PT Perusahaan Gas Negara | E17: Alifa | F17: RO Jakarta | G17: 46022
A18: 16 | B18: LPASI 2025 | C18: Jasa Pengembangan Aplikasi Gas Up (Coaching & Mentoring) | D18: PT Perusahaan Gas Negara | E18: Alifa | F18: RO Jakarta | G18: 46022
A19: 17 | B19: LPASI 2025 | C19: Pekerjaan Pengembangan Aplikasi PGN E-Lease Tahun 2025 | D19: PT Perusahaan Gas Negara | E19: Alifa | F19: RO Jakarta | G19: 46022
A20: 18 | C20: Website PGN | D20: PT Perusahaan Gas Negara | E20: Alifa | F20: RO Jakarta
A21: 19 | B21: LPASI 2025 | C21: Pengembangan Aplikasi Digitalisasi Berlangganan Gas Pelanggan Komersial Industri | D21: PT Perusahaan Gas Negara | E21: Alifa | F21: RO Jakarta | G21: 46022
A22: 20 | B22: kontrak tunggal | C22: Penyediaan Lisensi Piranti Lunak dan Annual Technical Support | D22: PT Perusahaan Gas Negara | E22: Alifa | F22: RO Jakarta | G22: 46357
A23: 21 | C23: PGN Register | D23: PT Perusahaan Gas Negara
A25: No | B25: Kontrak induk | C25: Kontrak Turunan | D25: Client | E25: Tanggal WO | F25: Nilai
A26: 1 | B26: MSAIS 2026 | C26: Jasa enhancement E-SMS | D26: PT Perusahaan Gas negara | E26: 46125 | F26: 140552312
A27: 2 | B27: MSAIS 2026 | C27: Pekerjaan Enhancement 16 KB Page File (Android), Multifactor Authentification (MFA) (Android & IOS) Serta Implementasi Progressive Web App (PWA) | D27: PT Perusahaan Gas negara | E27: 46181 | F27: 687369348
A28: 3 | B28: MSAIS 2026 | C28: Pekerjaan Pengelolaan & Dukungan Aplikasi Kepelangganan PGN Tahun 2026 | D28: PT Perusahaan Gas negara | E28: 46192 | F28: 695673676

Sheet DOKUMEN
A2: Project_ID | B2: Project_client | C2: Project Name | D2: Kontrak | E2: KAK | F2: Cost based | G2: Kertas kerja PSM | H2: TKDN | I2: Amandemen | J2: Keterangan | K2: Link
A3: BS-005 | B3: SAKA | C3: Pengadaan Sewa Aplikasi Absensi Online (Bimasakti) | D3: TRUE | E3: FALSE | F3: FALSE | G3: FALSE | H3: FALSE | I3: FALSE | K3: https://pgascom.sharepoint.com/:f:/s/DMO2-PCRM/IgBASDLQqhD3TLSMMW09hzt5AZ6yD-GxIDBIVVGSnRUi-WA?e=0baeY9
A4: MS-016 | B4: GGS | C4: Pengadaan Sewa Aplikasi Absensi Online (Bimasakti) | D4: TRUE | E4: FALSE | F4: FALSE | G4: FALSE | H4: FALSE | I4: FALSE | K4: https://pgascom.sharepoint.com/:f:/s/DMO2-PCRM/IgCMkAFcp6tbSrzK0fiK3O1FAToaLtKHG0Jp_uSopvBO2mE?e=7SitxB
A5: MS-019 | B5: PLI | C5: Jasa Pemeliharaan Sistem Kontrol dan Telekomunikasi Offtake Station (OTS) & Onshore Receiving Facilities (ORF) 2025-2026 | D5: TRUE | E5: TRUE | F5: FALSE | G5: FALSE | H5: TRUE | I5: FALSE | K5: https://pgascom.sharepoint.com/:f:/s/DMO2-PCRM/IgCywEI3sHKjQ7UX_9UywmDXAaqB1wp8xEfw-IzqdI74Kmc?e=tCe7Ip
A6: MS-020 | B6: NR | C6: Jasa Layanan Radio Komunikasi - Trunking | D6: TRUE | E6: FALSE | F6: FALSE | G6: FALSE | H6: FALSE | I6: TRUE | K6: https://pgascom.sharepoint.com/:f:/s/DMO2-PCRM/IgCn20bxH7GpRZson8QIVMSgAWJSvX86pexvHi8-mqtmd2Q?e=NtQ2av
A7: MS-044 | B7: PTM | C7: Penyediaan Layanan Platform Pilot Aplikasi Modern | D7: TRUE | E7: FALSE | F7: TRUE | G7: FALSE | H7: TRUE | I7: TRUE | K7: https://pgascom.sharepoint.com/:f:/s/DMO2-PCRM/IgCFYHqtUXTHTo8HLHl6nYTAAZwpnqoEvTj3nthjQ-rZZy4?e=KnxBIv
A8: MS-047 | B8: PGN | C8: Layanan Pengelolaan Aplikasi dan Solusi Integrasi Tahun 2025 | D8: TRUE | E8: TRUE | F8: FALSE | G8: FALSE | H8: TRUE | I8: FALSE | K8: https://pgascom.sharepoint.com/:f:/s/DMO2-PCRM/IgCn_ZZavLhuSbixBUVYsWz9AQ6xn-0iLYqeHx1TInNic5I?e=KBHcgb
A9: MS-081 | B9: PPN | C9: Pekerjaan Sewa Router Untuk Layanan Dual Link SPBU | D9: TRUE | E9: FALSE | F9: FALSE | G9: FALSE | H9: FALSE | I9: FALSE | K9: https://pgascom.sharepoint.com/:f:/s/DMO2-PCRM/IgDu9fQmkhFDR4aKpnKmxkpSAf1Mje4D9Iho9C_WrQp-zi4?e=atnQ1H
A10: MS-115 | B10: PPN | C10: Pekerjaan Maintenance CCTV & Infrastruktur PPN MOR1 FT Labuhan Deli | D10: TRUE | E10: FALSE | F10: TRUE | G10: TRUE | H10: FALSE | I10: FALSE | K10: https://pgascom.sharepoint.com/:f:/s/DMO2-PCRM/IgAAx5aYb-UjSrkWQQ1DzdzjAc51jV-QSMO3eRMsA25B57E?e=H8iNeU
A11: MS-117 | B11: SEML | C11: Provision of Document Management System ATS Muara Laboh | D11: TRUE | E11: FALSE | F11: FALSE | G11: FALSE | H11: TRUE | I11: FALSE
A12: MS-118 | B12: SERD | C12: Provision of Document Management System ATS Rantau Dedap | D12: TRUE | E12: FALSE | F12: FALSE | G12: FALSE | H12: TRUE | I12: FALSE
A13: MS-121 | B13: KPI | C13: Jasa Pendampingan Surveillance Sertifikasi ISO/IEC 27001:2022 di PT KPI | D13: TRUE | E13: TRUE | F13: TRUE | G13: TRUE | H13: TRUE | I13: FALSE | K13: https://pgascom.sharepoint.com/:f:/s/DMO2-PCRM/IgBHJcBF_-mWR6SFv7vCup3PAXpgcSgcI99DPIZgXlHE6kc?e=zmhNqe
A14: PS-000-00 | B14: PLI | C14: Pengadaan CCTV PT PGN LNG | D14: TRUE | E14: FALSE | F14: TRUE | G14: FALSE | H14: FALSE | I14: FALSE | K14: https://pgascom.sharepoint.com/:f:/s/DMO2-PCRM/IgAMhve6sr4RRKYNx_iv4nq3Afz7tqY1VwEeZn0qwTTu8qo?e=Z1DjWM
A15: PS-001-00 | B15: PTG | C15: Manage Service Layanan Printer, Scanner, Multimedia dan UPS System di PT Pertamina Gas | D15: TRUE | E15: TRUE | F15: TRUE | G15: FALSE | H15: FALSE | I15: TRUE | K15: https://pgascom.sharepoint.com/:f:/s/DMO2-PCRM/IgATDttzxz9aQZeHsGLAnwDZATEP3xSUAZSSWF2MJwjqvBA?e=0Bmlfo
A16: PS-003-00 | B16: WDR | C16: Pengadaan Sewa Aplikasi Absensi Online (Bimasakti) | D16: TRUE | E16: FALSE | F16: FALSE | G16: FALSE | H16: FALSE | I16: TRUE | K16: https://pgascom.sharepoint.com/:f:/s/DMO2-PCRM/IgCLqcYrWlmdS7dgHsvojo1nAft7SIc1P30G5fT1CS1xW3M?e=X2Asq1
A17: PS-004-00 | B17: PTM | C17: Pengelolaan & Pengembangan Servicedesk Shared Services Pertamina | D17: TRUE | E17: FALSE | F17: FALSE | G17: TRUE | H17: FALSE | I17: FALSE | K17: https://pgascom.sharepoint.com/:f:/s/DMO2-PCRM/IgBf4Pizf2GxSJfWj2kn-4JFASKNk8GNy4PLJdBaZGTRHs8?e=n23lr9
A18: PS-005-00 | B18: KJG | C18: Pengadaan Jasa penyediaan Perangkat Sistem Informasi | D18: TRUE | E18: TRUE | F18: TRUE | G18: FALSE | H18: FALSE | I18: TRUE | K18: https://pgascom.sharepoint.com/:f:/s/DMO2-PCRM/IgD0bK_uZP_TTJ5gAu1Xg4_WAQagLxaEkx9PGrJOoIOPeIE?e=AbzD1v
A19: PS-006-00 | B19: PSOL | C19: Implementasi Vulnerability Assessment & Penetration Test (VAPT) dan Technical Service Cyber Security | D19: TRUE | E19: TRUE | F19: TRUE | G19: FALSE | H19: FALSE | I19: FALSE | K19: https://pgascom.sharepoint.com/:f:/s/DMO2-PCRM/IgAyh4QjuxWsS5tJAeTBfdo3AQXqzRwCMUSe0xbCQ1ar7OE?e=8SBfTl
A20: PS-007-00 | B20: PGN | C20: Pekerjaan Penyediaan Layanan Sewa Server YKPP PGN | D20: TRUE | E20: FALSE | F20: FALSE | G20: FALSE | H20: FALSE | I20: FALSE | K20: https://pgascom.sharepoint.com/:f:/s/DMO2-PCRM/IgCMYLbsZNeVT6dRcsK4TKRmAZc-Dh3TsHc9RaCU0QRIP-w?e=BMzu0c
A21: PS-008-00 | B21: PGN | C21: Jasa Teknikal Asistensi Sistem Manajemen Informasi Legal (SMILE) 2024 | D21: TRUE | E21: FALSE | F21: FALSE | G21: FALSE | H21: FALSE | I21: TRUE | K21: https://pgascom.sharepoint.com/:f:/s/DMO2-PCRM/IgDMBBn0H-3wQbNZJJgN7t2qAcQC85UMrQQEabX5-LENHlI?e=orzmib
A22: PS-009-00 | B22: NR | C22: Jasa Implementasi Security Information Event Management (SIEM) dan Security Operation Center (SOC) | D22: TRUE | E22: TRUE | F22: TRUE | G22: FALSE | H22: FALSE | I22: FALSE | K22: https://pgascom.sharepoint.com/:f:/s/DMO2-PCRM/IgC_AZMGMaAmRI7jwYWmK3w-AX2BsfXSa6ZO324MXWJSnJk?e=erhcY6
A23: PS-010-00 | B23: PTM | C23: Penyediaan Jasa Dukungan Operasional Fungsi Shared Services ICT Tahun 2025-2026 | D23: TRUE | E23: FALSE | F23: TRUE | G23: FALSE | H23: FALSE | I23: FALSE | K23: https://pgascom.sharepoint.com/:f:/s/DMO2-PCRM/IgBaofmynKRRTKCWwr7jh_SyAXmKyaVz9E07YGtlpNLY0oE?e=pXRO9l
A24: PS-011-00 | B24: PGN | C24: Penyediaan Lisensi Piranti Lunak dan Annual Technical Support | D24: FALSE | E24: FALSE | F24: FALSE | G24: FALSE | H24: FALSE | I24: FALSE
A25: PS-012-00 | B25: PTM | C25: Pengadaan Jasa Penyediaan Endpoint Security 2026-2027 | D25: TRUE | E25: FALSE | F25: TRUE | G25: FALSE | H25: TRUE | I25: FALSE | K25: https://pgascom.sharepoint.com/:f:/s/DMO2-PCRM/IgDRM-4yXdlPTpqB1FVE65J0AVRTEzEzX9HhakiexEtxEFc?e=T4PzVy
A26: PS-013-00 | B26: PTM | C26: Pengadaan Sewa Perangkat Storage san NTP Server Pertamina | D26: TRUE | E26: TRUE | F26: TRUE | G26: FALSE | H26: TRUE | I26: TRUE | K26: https://pgascom.sharepoint.com/:f:/s/DMO2-PCRM/IgCBB8gzprowQ6SOv9SA-qzBAarzaSFyTBjkYXgZeSTMvv0?e=VhHdGP
A27: PS-014-00 | B27: PTM | C27: Penyediaan Jasa Layanan Offline Backup AWS Phase 1 | D27: TRUE | E27: FALSE | F27: FALSE | G27: FALSE | H27: TRUE | I27: FALSE | K27: https://pgascom.sharepoint.com/:f:/s/DMO2-PCRM/IgAwpxfCI-h0Raklv4LGDvQnATQcd0KLQcdKkOsEOW4B5ZY?e=LctLWX
A28: PS-015-00 | B28: PTM | C28: Tindak Lanjut Pekerjaan Jasa Managed Service Security Assessment (MSSA) | D28: TRUE | E28: TRUE | F28: TRUE | G28: FALSE | H28: TRUE | I28: FALSE | K28: https://pgascom.sharepoint.com/:f:/s/DMO2-PCRM/IgCZNoNtBVFxRLEaLnoH06RtAWk2WWZFuu3McPGzv5a2N08?e=mvvhhI
A29: PS-016-00 | B29: PGN | C29: Jasa Managed Service Pengelolaan Layanan Pelanggan Melalui Contact Center 2025-2027 | D29: TRUE | E29: TRUE | F29: TRUE | G29: TRUE | H29: TRUE | I29: FALSE | K29: https://pgascom.sharepoint.com/:f:/s/DMO2-PCRM/IgBlYpRzviokR5NEJLwcitJiAcM3n63l-8eJr6w6pcvfGJ8?e=E6gXhq
A30: PS-017-00 | B30: PGN | C30: Jasa Penyediaan Perangkat Multimedia dan Peralatan Pendukung Ruang Integrated Monitoring Center (IMOC) | D30: TRUE | E30: FALSE | F30: TRUE | G30: FALSE | H30: FALSE | I30: FALSE | K30: https://pgascom.sharepoint.com/:f:/s/DMO2-PCRM/IgAIXPUMtHU6QYLG8SqFF2hqAWjcRBN25TZWAYQm7eex9jI?e=CpgalX
A31: PS-018-00 | B31: PGN | C31: Managed Service Aplication Integration Solutions (MSAIS) Tahun 2026 | D31: TRUE | E31: TRUE | F31: TRUE | G31: TRUE | H31: TRUE | I31: FALSE | K31: https://pgascom.sharepoint.com/:f:/s/DMO2-PCRM/IgAg-LwPCp9uT5JuKsrMvg0sAeR75PhJGWTM5Ie2WDdFYWI?e=tOO9aA
A32: PS-019-00 | B32: PGN | C32: Managed Service Backup Management (Vinchin) | D32: TRUE | E32: TRUE | F32: FALSE | G32: TRUE | H32: TRUE | I32: FALSE | K32: https://pgascom.sharepoint.com/:f:/s/DMO2-PCRM/IgCWt-04uHYWSZX44lNsSCfMATbuBCw45Q3e4LH5vABrchA?e=iXS2M2
A33: PS-020-00 | B33: PGN | C33: Managed Service Cyber Security (MSCS) Tahun 2026 | D33: TRUE | E33: TRUE | F33: TRUE | G33: FALSE | H33: TRUE | I33: FALSE | K33: https://pgascom.sharepoint.com/:f:/s/DMO2-PCRM/IgA2DrHZ4QH2Qpkn3DfEN37mAcVXRaAYWi1eLZwKQadKIgg?e=GO7Qht
A34: PS-021-00 | B34: PGN | C34: Managed Service OT Security (MSOT) Tahun 2026 - 2028 | D34: TRUE | E34: TRUE | F34: TRUE | G34: TRUE | H34: TRUE | I34: FALSE | K34: https://pgascom.sharepoint.com/:f:/s/DMO2-PCRM/IgDBZzzozJyATIV0zPFXNh9wAV6qyjKnXEBkqkFw9_3lG_k?e=dWLn5O
A35: PS-022-00 | B35: PGN | C35: Managed Service Sewa Infrastruktur Data Center (Aletra) | D35: TRUE | E35: TRUE | F35: TRUE | G35: FALSE | H35: FALSE | I35: FALSE | K35: https://pgascom.sharepoint.com/:f:/s/DMO2-PCRM/IgCTK0e_rgt1RL2fIkGiu1l2AXpDEiyNm9VOcnriTKyYn6M?e=OyXaHQ
A36: PS-023-00 | B36: PGN | C36: Managed Service Teknologi Informasi (MSTI) 2025 | D36: TRUE | E36: TRUE | F36: FALSE | G36: FALSE | H36: FALSE | I36: FALSE | K36: https://pgascom.sharepoint.com/:f:/s/DMO2-PCRM/IgBgihMLdWI5ToCPTTCFywLAAcMI9VkAhI20woHPnHEXeHk?e=BXz8wB
... A44: PS-030-00 | B44: PGN | C44: Sewa Perangkat Infrastruktur Teknologi Informasi (Sangfor) | D44: TRUE | E44: TRUE | F44: TRUE | G44: FALSE | H44: FALSE | I44: TRUE | K44: https://pgascom.sharepoint.com/:f:/s/DMO2-PCRM/IgB9WQGFSm8PQ7zJz4lU80CNAYy-YpYvdqb5JBdjAgGVlhw?e=uDtFCJ
A45: PS-031-00 | B45: PGN | C45: Penyediaan Personil Tenaga Alih Daya (TAD) di PT Perusahaan Gas Negara (PGN) HSSE Untuk Rencana Pekerjaan PGN Digital HSSE Campaign Tahun 2026 | D45: FALSE | E45: FALSE | F45: FALSE | G45: FALSE | H45: FALSE | I45: FALSE
A46: PS-032-00 | B46: PGN | C46: Penyediaan Aplikasi Point of Sales untuk Pemberdayaan Aset | D46: TRUE | E46: TRUE | F46: TRUE | G46: FALSE | H46: TRUE | I46: FALSE | K46: https://pgascom.sharepoint.com/:f:/s/DMO2-PCRM/IgAruXOx_eIDRqpPLfXCDInEAYG7a-YSFaWzVZDIlflQ8nU?e=40V6kH
A47: PS-033-00 | B47: PGN | C47: Managed Service Cyber Security Awareness 2026 | D47: FALSE | E47: TRUE | F47: TRUE | G47: FALSE | H47: TRUE | I47: FALSE | K47: https://pgascom.sharepoint.com/:f:/s/DMO2-PCRM/IgAb5S6-_gmyRrqQ0lEcwlozAS5AH2yHsLjFXARzDzSArpY?e=FNNVfh
A48: PS-034-00 | B48: PLI | C48: Jasa Pemeliharaan Sistem Kontrol dan Telekomunikasi Offtake Station (OTS) & Onshore Receiving Facilities (ORF) 2026-2027 | D48: FALSE | E48: FALSE | F48: TRUE | G48: TRUE | H48: FALSE | I48: FALSE | K48: https://pgascom.sharepoint.com/:f:/s/DMO2-PCRM/IgAQQ4Gu1ds-QLAqfliMziBlAeq6s8-FcvWplmxPSpD14vQ?e=ZVQ9fu
...

Sheet PIC
A2: Project_ID | B2: Project_client | C2: Project Name | D2: Account Manager | E2: Pre-Sales | F2: Project Manager | G2: Service Manager
A3: BS-005 | B3: SAKA | C3: Pengadaan Sewa Aplikasi Absensi Online (Bimasakti)
A4: MS-016 | B4: GGS | C4: Pengadaan Sewa Aplikasi Absensi Online (Bimasakti)
A5: MS-019 | B5: PLI | C5: Jasa Pemeliharaan Sistem Kontrol dan Telekomunikasi Offtake Station (OTS) & Onshore Receiving Facilities (ORF)
A6: MS-020 | B6: NR | C6: Jasa Layanan Radio Komunikasi - Trunking
A7: MS-044 | B7: PTM | C7: Penyediaan Layanan Platform Pilot Aplikasi Modern
A8: MS-081 | B8: PPN | C8: Pekerjaan Sewa Router Untuk Layanan Dual Link SPBU
A9: PS-000-00 | B9: PLI | C9: Pengadaan CCTV PT PGN LNG
A10: PS-001-00 | B10: PTG | C10: Manage Service Layanan Printer, Scanner, Multimedia dan UPS System di PT Pertamina Gas
A11: PS-003-00 | B11: WDR | C11: Pengadaan Sewa Aplikasi Absensi Online (Bimasakti)
A12: PS-004-00 | B12: PTM | C12: Pengelolaan & Pengembangan Servicedesk Shared Services Pertamina
A13: PS-005-00 | B13: KJG | C13: Pengadaan Jasa penyediaan Perangkat Sistem Informasi
A14: PS-006-00 | B14: PSOL | C14: Implementasi Vulnerability Assessment & Penetration Test (VAPT) dan Technical Service Cyber Security
... A61: PS-055-00 | B61: PPN | C61: Jasa Keamanan Operasi Cyber Security PT Kilang Pertamina Internasional
A62: MS-115
A63: MS-116
A64: MS-117
A65: MS-118
A66: MS-119
A67: MS-120

Sheet TKDN
C1: =SUBTOTAL(3,C3:C50) -> 46 | F1: 2026 | R1: 2027 | AD1: 2028 | AP1: 2029
A2: ID | B2: Client | C2: Project Name | D2: TKDN | E2: Description | F2: Jan-26 | G2: Feb-26 | H2: Mar-26 | I2: Apr-26 | J2: Mei-26 | K2: Jun-26 | L2: Jul-26 | M2: Agu-26 | N2: Sep-26 | O2: Okt-26 | P2: Nov-26 | Q2: Des-26 | R2: Jan-27 | S2: Feb-27 | T2: Mar-27 | U2: Apr-27 | V2: Mei-27 | W2: Jun-27 | X2: Jul-27 | Y2: Agu-27 | Z2: Sep-27 | AA2: Okt-27 | AB2: Nov-27 | AC2: Des-27 | AD2: Jan-28 | AE2: Feb-28 | AF2: Mar-28 | AG2: Apr-28 | AH2: Mei-28 | AI2: Jun-28 | AJ2: Jul-28 | AK2: Agu-28 | AL2: Sep-28 | AM2: Okt-28 | AN2: Nov-28 | AO2: Des-28 | AP2: Jan-29 | AQ2: Feb-29 | AR2: Mar-29 | AS2: Apr-29 | AT2: Mei-29 | AU2: Jun-29 | AV2: Jul-29 | AW2: Agu-29 | AX2: Sep-29 | AY2: Okt-29 | AZ2: Nov-29 | BA2: Des-29
A3: MS-019 | B3: PLI | C3: Jasa Pemeliharaan Sistem Kontrol dan Telekomunikasi Offtake Station (OTS) & Onshore Receiving Facilities (ORF) | D3: 0.79 | G3: VERIFIKASI
A4: PS-004-00 | B4: PTM | C4: Pengelolaan & Pengembangan Servicedesk Shared Services Pertamina | D4: 89,60% | E4: dokumen komitmen
A5: PS-005-00 | B5: KJG | C5: Pengadaan Jasa penyediaan Perangkat Sistem Informasi | D5: 0.4 | E5: dokumen komitmen
A6: PS-006-00 | B6: PSOL | C6: Implementasi Vulnerability Assessment & Penetration Test (VAPT) dan Technical Service Cyber Security | D6: 0.8923 | M6: VERIFIKASI
A7: PS-008-00 | B7: PGN | C7: Jasa Teknikal Asistensi Sistem Manajemen Informasi Legal (SMILE) | D7: 0.9547 | E7: dokumen komitmen
A8: PS-009-00 | B8: NR | C8: Jasa Implementasi Security Information Event Management (SIEM) dan Security Operation Center (SOC) | D8: 0.7386 | E8: dokumen komitmen
A9: PS-011-00 | B9: PGN | C9: Penyediaan Lisensi Piranti Lunak dan Annual Technical Support | D9: 33,77%
A10: PS-012-00 | B10: PTM | C10: Pengadaan Jasa Penyediaan Endpoint Security 2026-2027 | D10: 0.0111 | T10: VERIFIKASI
A11: PS-013-00 | B11: PTM | C11: Pengadaan Sewa Perangkat Storage san NTP Server Pertamina | D11: 0.7119 | L11: MONITORING | Q11: MONITORING | X11: MONITORING | AC11: MONITORING | AJ11: VERIFIKASI
A12: PS-014-00 | B12: PTM | C12: Penyediaan Jasa Layanan Offline Backup AWS Phase 1 | D12: 0.3478 | H12: MONITORING | N12: VERIFIKASI
A13: PS-015-00 | B13: PTM | C13: Tindak Lanjut Pekerjaan Jasa Managed Service Security Assessment (MSSA) | D13: 0.3546 | I13: MONITORING | O13: VERIFIKASI
A14: PS-016-00 | B14: PGN | C14: Jasa Managed Service Pengelolaan Layanan Pelanggan Melalui Contact Center 2025-2027 | D14: 89,20% | N14: MONITORING | Z14: VERIFIKASI
A15: PS-017-00 | B15: PGN | C15: Jasa Penyediaan Perangkat Multimedia dan Peralatan Pendukung Ruang Integrated Monitoring Center (IMOC) | D15: 0.8513 | E15: dokumen komitmen | AK15: VERIFIKASI
A16: PS-018-00 | B16: PGN | C16: Managed Service Aplication Integration Solutions (MSAIS) Tahun 2026 | D16: 84,45% | Q16: VERIFIKASI
A17: PS-019-00 | B17: PGN | C17: Managed Service Backup Management (Vinchin) | D17: 0.5031 | K17: MONITORING | Q17: MONITORING | W17: MONITORING | AC17: VERIFIKASI
A18: PS-020-00 | B18: PGN | C18: Managed Service Cyber Security (MSCS) Tahun 2026 | D18: 0.6632 | F18: MONITORING | G18: MONITORING | H18: MONITORING | I18: MONITORING | J18: MONITORING | K18: MONITORING | L18: MONITORING | M18: MONITORING | N18: MONITORING | O18: MONITORING | P18: MONITORING | Q18: VERIFIKASI
A19: PS-021-00 | B19: PGN | C19: Managed Service OT Security (MSOT) Tahun 2026 - 2028 | D19: 30,44% | K19: MONITORING | Q19: MONITORING | W19: MONITORING | AC19: MONITORING | AI19: MONITORING | AO19: VERIFIKASI
A20: PS-022-00 | B20: PGN | C20: Managed Service Sewa Infrastruktur Data Center (Aletra) | D20: 0.66 | E20: dokumen komitmen | AC20: VERIFIKASI
A21: PS-023-00 | B21: PGN | C21: Managed Service Teknologi Informasi (MSTI) 2026 | D21: 0.643 | Q21: VERIFIKASI
A22: PS-024-00 | B22: PGN | C22: Pekerjaan Jasa Operasi dan Pemeliharaan Terintegrasi Gas Management System (PJOPTGMS) | D22: 0.5918 | G22: MONITORING | S22: MONITORING | AE22: VERIFIKASI
A23: PS-025-00 | B23: PGN | C23: Pekerjaan Jasa Sewa Penyediaan Collocation Master Data Center dan Backup data Center | D23: 0.7741 | E23: dokumen komitmen | Q23: VERIFIKASI
A24: PS-026-00 | B24: PGN | C24: Pengadaan Jasa Managed Service E-KYC | D24: 58,56% | F24: MONITORING | I24: MONITORING | L24: MONITORING | O24: MONITORING | Q24: VERIFIKASI
A25: PS-027-00 | B25: PGN | C25: Penyediaan Jasa Layanan Notifikasi SMS Penagihan Piutang Pelanggan Tahun 2026 | D25: 0.9635 | J25: MONITORING | M25: MONITORING | Q25: VERIFIKASI
A26: PS-028-00 | B26: PGN | C26: Penyediaan Layanan Sistem Radio Komunikasi 2025-2027 | D26: 75,57% | E26: dokumen komitmen | AC26: VERIFIKASI
A27: PS-029-00 | B27: PGN | C27: Penyediaan Lisensi Piranti Lunak Periode IV (Google Maps) | D27: 0.0757 | L27: MONITORING | Q27: MONITORING | X27: MONITORING | AC27: MONITORING | AJ27: MONITORING | AO27: VERIFIKASI
A28: PS-030-00 | B28: PGN | C28: Sewa Perangkat Infrastruktur Teknologi Informasi (Sangfor) | D28: 0.4692 | E28: dokumen komitmen | AP28: VERIFIKASI
A29: PS-031-00 | B29: PGN | C29: Penyediaan Personil Tenaga Alih Daya (TAD) di PT Perusahaan Gas Negara (PGN) HSSE Untuk Rencana Pekerjaan PGN Digital HSSE Campaign Tahun 2026 | D29: TBC | E29: dokumen komitmen
A30: PS-032-00 | B30: PGN | C30: Penyediaan Aplikasi Point of Sales untuk Pemberdayaan Aset | D30: 0.8661 | K30: MONITORING | N30: MONITORING | Q30: VERIFIKASI
A31: PS-033-00 | B31: PGN | C31: Managed Service Cyber Security Awareness | D31: 0.5702 | F31: MONITORING | G31: MONITORING | H31: MONITORING | I31: MONITORING | J31: MONITORING | K31: MONITORING | L31: MONITORING | M31: MONITORING | N31: MONITORING | O31: MONITORING | P31: MONITORING | Q31: VERIFIKASI
A32: PS-034-00 | B32: PLI | C32: Jasa Pemeliharaan Sistem Kontrol dan Telekomunikasi Offtake Station (OTS) & Onshore Receiving Facilities (ORF) | D32: 0.79 | E32: dokumen komitmen | J32: MONITORING | M32: MONITORING | P32: MONITORING | S32: VERIFIKASI
A33: PS-035-00 | B33: PTG | C33: Layanan Sewa Perangkat Server dan Network Teknologi Informasi dan Layanan Sewa Perangkat Infrastruktur Teknologi Informasi SPO Nusantara | D33: TBC | E33: dokumen komitmen
A34: PS-036-00 | B34: PTG | C34: Manage Service Layanan Perangkat Command Crisis Center PT Pertamina Gas | D34: 0.71 | E34: dokumen komitmen
A35: PS-039-00 | B35: PTG | C35: Managed Service Sewa layanan IP Phone System | D35: 0.5646 | E35: dokumen komitmen
A36: PS-040-00 | B36: PLI | C36: Pekerjaan Layanan Cloud (dan VAPT) | D36: 0.75 | E36: dokumen komitmen | AC36: VERIFIKASI
A37: PS-043-00 | B37: PTG | C37: Pengelolaan Integrasi Data dan Pemeliharaan Sistem Data Acquisition Transportasi Minyak & Gas Bumi | D37: 0.9702 | E37: dokumen komitmen | V37: VERIFIKASI
A38: PS-044-00 | B38: PPN | C38: Pengadaan Implementasi Security Operation Center (SOC) di Kantor Pusat Wisma Tugu II | D38: 0.3577 | J38: MONITORING | P38: MONITORING | V38: MONITORING | AB38: MONITORING | AH38: MONITORING | AN38: VERIFIKASI
A39: PS-045-00 | B39: PIS | C39: Penyediaan Perangkat Multimedia Ballroom dan Mini Galery | D39: 0.7519 | E39: dokumen komitmen | AY39: VERIFIKASI
A40: PS-046-00 | B40: PET | C40: Sewa Perangkat Radio Komunikasi di TLPG Tanjung Sekong, IT Tanjung Uban, FT Pulau Sambu, FT Kotabaru dan FT Baubau | D40: 0.7674 | E40: dokumen komitmen | AM40: VERIFIKASI
...

Sheet REALISASI 2026
B2: PROJECT NAME | C2: All Project
B3: CUSTOMER | C3: ALL CUSTOMER
B4: PERIODE | C4: 2026
B6: NO | C6: KODE PROJECT | D6: NAMA PROJECT | E6: ITEM BIAYA | F6: SATUAN KERJA | G6: PIC | H6: PERIODE | I6: REALISASI BIAYA | J6: STATUS | K6: VENDOR | L6: SIFAT | M6: LINK EVIDENCE | N6: Tahun | O6: Kolom1
K7: 0 | M7: https://pgascom.sharepoint.com/:f:/s/DMO2-PCRM/IgAtXwuElMa_S4ltRuIZ2mJTAeEOdK2ZKM055kdpTEpNhk8?e=KE5ciu | N7: 2026
C8: PS-024-00 | D8: {=_xlfn.XLOOKUP(Tabel2[[#This Row],[KODE PROJECT]], _xlfn.VSTACK('KODE PROJECT BARU'!$B$5:$B$98, 'KODE PROJECT BARU'!$C$5:$C$98), _xlfn.VSTACK('KODE PROJECT BARU'!$E$5:$E$98, 'KODE PROJECT BARU'!$E$5:$E$98), "Tidak Ditemukan", 0, 1)} -> #NAME? | E8: UPAH | F8: DMO | G8: Ulfa | H8: JANUARI | I8: =851433857+12333257 -> 863767114 | J8: PAID | K8: PERSADA | L8: MONTHLY | N8: 2026
C9: PS-024-00 | D9: {=_xlfn.XLOOKUP(Tabel2[[#This Row],[KODE PROJECT]], _xlfn.VSTACK('KODE PROJECT BARU'!$B$5:$B$98, 'KODE PROJECT BARU'!$C$5:$C$98), _xlfn.VSTACK('KODE PROJECT BARU'!$E$5:$E$98, 'KODE PROJECT BARU'!$E$5:$E$98), "Tidak Ditemukan", 0, 1)} -> #NAME? | E9: UPAH | F9: DMO | G9: Ulfa | H9: FEBRUARI | I9: =862153641+11055476 -> 873209117 | J9: PAID | K9: PERSADA | L9: MONTHLY | N9: 2026
C10: PS-024-00 | D10: {=_xlfn.XLOOKUP(Tabel2[[#This Row],[KODE PROJECT]], _xlfn.VSTACK('KODE PROJECT BARU'!$B$5:$B$98, 'KODE PROJECT BARU'!$C$5:$C$98), _xlfn.VSTACK('KODE PROJECT BARU'!$E$5:$E$98, 'KODE PROJECT BARU'!$E$5:$E$98), "Tidak Ditemukan", 0, 1)} -> #NAME? | E10: UPAH | F10: DMO | G10: Ulfa | H10: MARET | I10: =869057456-10926705 -> 858130751 | J10: PAID | K10: PERSADA | L10: MONTHLY | N10: 2026
C11: PS-024-00 | D11: {=_xlfn.XLOOKUP(Tabel2[[#This Row],[KODE PROJECT]], _xlfn.VSTACK('KODE PROJECT BARU'!$B$5:$B$98, 'KODE PROJECT BARU'!$C$5:$C$98), _xlfn.VSTACK('KODE PROJECT BARU'!$E$5:$E$98, 'KODE PROJECT BARU'!$E$5:$E$98), "Tidak Ditemukan", 0, 1)} -> #NAME? | E11: TALI KASIH | F11: DMO | G11: Ulfa | H11: MARET | I11: 115194767 | J11: PAID | K11: PERSADA | L11: OTC | N11: 2026
C12: PS-024-00 | D12: {=_xlfn.XLOOKUP(Tabel2[[#This Row],[KODE PROJECT]], _xlfn.VSTACK('KODE PROJECT BARU'!$B$5:$B$98, 'KODE PROJECT BARU'!$C$5:$C$98), _xlfn.VSTACK('KODE PROJECT BARU'!$E$5:$E$98, 'KODE PROJECT BARU'!$E$5:$E$98), "Tidak Ditemukan", 0, 1)} -> #NAME? | E12: THRK | F12: DMO | G12: Ulfa | H12: MARET | I12: 592126292 | J12: PAID | K12: PERSADA | L12: OTC | N12: 2026
C13: PS-024-00 | D13: {=_xlfn.XLOOKUP(Tabel2[[#This Row],[KODE PROJECT]], _xlfn.VSTACK('KODE PROJECT BARU'!$B$5:$B$98, 'KODE PROJECT BARU'!$C$5:$C$98), _xlfn.VSTACK('KODE PROJECT BARU'!$E$5:$E$98, 'KODE PROJECT BARU'!$E$5:$E$98), "Tidak Ditemukan", 0, 1)} -> #NAME? | E13: SPPD | F13: DMO | G13: Ulfa | H13: JANUARI | I13: 46479352 | J13: PAID | K13: PERSADA | L13: OTC | N13: 2026
C14: PS-024-00 | D14: {=_xlfn.XLOOKUP(Tabel2[[#This Row],[KODE PROJECT]], _xlfn.VSTACK('KODE PROJECT BARU'!$B$5:$B$98, 'KODE PROJECT BARU'!$C$5:$C$98), _xlfn.VSTACK('KODE PROJECT BARU'!$E$5:$E$98, 'KODE PROJECT BARU'!$E$5:$E$98), "Tidak Ditemukan", 0, 1)} -> #NAME? | E14: SPPD | F14: DMO | G14: Ulfa | H14: FEBRUARI | I14: 105094644 | J14: PAID | K14: PERSADA | L14: OTC | N14: 2026
C15: PS-024-00 | D15: {=_xlfn.XLOOKUP(Tabel2[[#This Row],[KODE PROJECT]], _xlfn.VSTACK('KODE PROJECT BARU'!$B$5:$B$98, 'KODE PROJECT BARU'!$C$5:$C$98), _xlfn.VSTACK('KODE PROJECT BARU'!$E$5:$E$98, 'KODE PROJECT BARU'!$E$5:$E$98), "Tidak Ditemukan", 0, 1)} -> #NAME? | E15: SPPD | F15: DMO | G15: Ulfa | H15: MARET | I15: 54037546 | J15: PAID | K15: PERSADA | L15: OTC | N15: 2026
C16: PS-028-00 | D16: {=_xlfn.XLOOKUP(Tabel2[[#This Row],[KODE PROJECT]], _xlfn.VSTACK('KODE PROJECT BARU'!$B$5:$B$98, 'KODE PROJECT BARU'!$C$5:$C$98), _xlfn.VSTACK('KODE PROJECT BARU'!$E$5:$E$98, 'KODE PROJECT BARU'!$E$5:$E$98), "Tidak Ditemukan", 0, 1)} -> #NAME? | E16: UPAH | F16: DMO | G16: Ulfa | H16: JANUARI | I16: =20280832+289712 -> 20570544 | J16: PAID | K16: PERSADA | L16: MONTHLY | N16: 2026
C17: PS-028-00 | D17: {=_xlfn.XLOOKUP(Tabel2[[#This Row],[KODE PROJECT]], _xlfn.VSTACK('KODE PROJECT BARU'!$B$5:$B$98, 'KODE PROJECT BARU'!$C$5:$C$98), _xlfn.VSTACK('KODE PROJECT BARU'!$E$5:$E$98, 'KODE PROJECT BARU'!$E$5:$E$98), "Tidak Ditemukan", 0, 1)} -> #NAME? | E17: UPAH | F17: DMO | G17: Ulfa | H17: FEBRUARI | I17: =16470110+12240515 -> 28710625 | J17: PAID | K17: PERSADA | L17: MONTHLY | N17: 2026
C18: PS-028-00 | D18: {=_xlfn.XLOOKUP(Tabel2[[#This Row],[KODE PROJECT]], _xlfn.VSTACK('KODE PROJECT BARU'!$B$5:$B$98, 'KODE PROJECT BARU'!$C$5:$C$98), _xlfn.VSTACK('KODE PROJECT BARU'!$E$5:$E$98, 'KODE PROJECT BARU'!$E$5:$E$98), "Tidak Ditemukan", 0, 1)} -> #NAME? | E18: UPAH | F18: DMO | G18: Ulfa | H18: MARET | I18: =10575923-1154462 -> 9421461 | J18: PAID | K18: PERSADA | L18: MONTHLY | N18: 2026
C19: PS-028-00 | D19: {=_xlfn.XLOOKUP(Tabel2[[#This Row],[KODE PROJECT]], _xlfn.VSTACK('KODE PROJECT BARU'!$B$5:$B$98, 'KODE PROJECT BARU'!$C$5:$C$98), _xlfn.VSTACK('KODE PROJECT BARU'!$E$5:$E$98, 'KODE PROJECT BARU'!$E$5:$E$98), "Tidak Ditemukan", 0, 1)} -> #NAME? | E19: TALI KASIH | F19: DMO | G19: Ulfa | H19: MARET | I19: 1500000 | J19: PAID | K19: PERSADA | L19: OTC | N19: 2026
C20: PS-028-00 | D20: {=_xlfn.XLOOKUP(Tabel2[[#This Row],[KODE PROJECT]], _xlfn.VSTACK('KODE PROJECT BARU'!$B$5:$B$98, 'KODE PROJECT BARU'!$C$5:$C$98), _xlfn.VSTACK('KODE PROJECT BARU'!$E$5:$E$98, 'KODE PROJECT BARU'!$E$5:$E$98), "Tidak Ditemukan", 0, 1)} -> #NAME? | E20: THRK | F20: DMO | G20: Ulfa | H20: MARET | I20: 7584700 | J20: PAID | K20: PERSADA | L20: OTC | N20: 2026
C21: PS-028-00 | D21: {=_xlfn.XLOOKUP(Tabel2[[#This Row],[KODE PROJECT]], _xlfn.VSTACK('KODE PROJECT BARU'!$B$5:$B$98, 'KODE PROJECT BARU'!$C$5:$C$98), _xlfn.VSTACK('KODE PROJECT BARU'!$E$5:$E$98, 'KODE PROJECT BARU'!$E$5:$E$98), "Tidak Ditemukan", 0, 1)} -> #NAME? | E21: SPPD | F21: DMO | G21: Ulfa | H21: FEBRUARI | I21: 6088574 | J21: PAID | K21: PERSADA | L21: OTC | N21: 2026
C22: MS-019 | D22: {=_xlfn.XLOOKUP(Tabel2[[#This Row],[KODE PROJECT]], _xlfn.VSTACK('KODE PROJECT BARU'!$B$5:$B$98, 'KODE PROJECT BARU'!$C$5:$C$98), _xlfn.VSTACK('KODE PROJECT BARU'!$E$5:$E$98, 'KODE PROJECT BARU'!$E$5:$E$98), "Tidak Ditemukan", 0, 1)} -> #NAME? | E22: UPAH | F22: DMO | G22: Ulfa | H22: JANUARI | I22: =29356172-1314774 -> 28041398 | J22: PAID | K22: PERSADA | L22: MONTHLY | N22: 2026
C23: MS-019 | D23: {=_xlfn.XLOOKUP(Tabel2[[#This Row],[KODE PROJECT]], _xlfn.VSTACK('KODE PROJECT BARU'!$B$5:$B$98, 'KODE PROJECT BARU'!$C$5:$C$98), _xlfn.VSTACK('KODE PROJECT BARU'!$E$5:$E$98, 'KODE PROJECT BARU'!$E$5:$E$98), "Tidak Ditemukan", 0, 1)} -> #NAME? | E23: UPAH | F23: DMO | G23: Ulfa | H23: FEBRUARI | I23: =29356172-394114 -> 28962058 | J23: PAID | K23: PERSADA | L23: MONTHLY | N23: 2026
C24: MS-019 | D24: {=_xlfn.XLOOKUP(Tabel2[[#This Row],[KODE PROJECT]], _xlfn.VSTACK('KODE PROJECT BARU'!$B$5:$B$98, 'KODE PROJECT BARU'!$C$5:$C$98), _xlfn.VSTACK('KODE PROJECT BARU'!$E$5:$E$98, 'KODE PROJECT BARU'!$E$5:$E$98), "Tidak Ditemukan", 0, 1)} -> #NAME? | E24: UPAH | F24: DMO | G24: Ulfa | H24: MARET | I24: =29356172+2477355 -> 31833527 | J24: PAID | K24: PERSADA | L24: MONTHLY | N24: 2026
C25: MS-019 | D25: {=_xlfn.XLOOKUP(Tabel2[[#This Row],[KODE PROJECT]], _xlfn.VSTACK('KODE PROJECT BARU'!$B$5:$B$98, 'KODE PROJECT BARU'!$C$5:$C$98), _xlfn.VSTACK('KODE PROJECT BARU'!$E$5:$E$98, 'KODE PROJECT BARU'!$E$5:$E$98), "Tidak Ditemukan", 0, 1)} -> #NAME? | E25: TALI KASIH | F25: DMO | G25: Ulfa | H25: MARET | I25: 4500000 | J25: PAID | K25: PERSADA | L25: OTC | N25: 2026
C26: MS-019 | D26: {=_xlfn.XLOOKUP(Tabel2[[#This Row],[KODE PROJECT]], _xlfn.VSTACK('KODE PROJECT BARU'!$B$5:$B$98, 'KODE PROJECT BARU'!$C$5:$C$98), _xlfn.VSTACK('KODE PROJECT BARU'!$E$5:$E$98, 'KODE PROJECT BARU'!$E$5:$E$98), "Tidak Ditemukan", 0, 1)} -> #NAME? | E26: THRK | F26: DMO | G26: Ulfa | H26: MARET | I26: 20807845 | J26: PAID | K26: PERSADA | L26: OTC | N26: 2026
C27: MS-019 | D27: {=_xlfn.XLOOKUP(Tabel2[[#This Row],[KODE PROJECT]], _xlfn.VSTACK('KODE PROJECT BARU'!$B$5:$B$98, 'KODE PROJECT BARU'!$C$5:$C$98), _xlfn.VSTACK('KODE PROJECT BARU'!$E$5:$E$98, 'KODE PROJECT BARU'!$E$5:$E$98), "Tidak Ditemukan", 0, 1)} -> #NAME? | E27: SPPD | F27: DMO | G27: Ulfa | H27: JANUARI | I27: 1983761 | J27: PAID | K27: PERSADA | L27: OTC | N27: 2026
C28: MS-019 | D28: {=_xlfn.XLOOKUP(Tabel2[[#This Row],[KODE PROJECT]], _xlfn.VSTACK('KODE PROJECT BARU'!$B$5:$B$98, 'KODE PROJECT BARU'!$C$5:$C$98), _xlfn.VSTACK('KODE PROJECT BARU'!$E$5:$E$98, 'KODE PROJECT BARU'!$E$5:$E$98), "Tidak Ditemukan", 0, 1)} -> #NAME? | E28: SPPD | F28: DMO | G28: Ulfa | H28: FEBRUARI | I28: 7686569 | J28: PAID | K28: PERSADA | L28: OTC | N28: 2026
C29: PS-046-00 | D29: {=_xlfn.XLOOKUP(Tabel2[[#This Row],[KODE PROJECT]], _xlfn.VSTACK('KODE PROJECT BARU'!$B$5:$B$98, 'KODE PROJECT BARU'!$C$5:$C$98), _xlfn.VSTACK('KODE PROJECT BARU'!$E$5:$E$98, 'KODE PROJECT BARU'!$E$5:$E$98), "Tidak Ditemukan", 0, 1)} -> #NAME? | E29: UPAH | F29: DMO | G29: Ulfa | H29: JANUARI | I29: 7607974 | J29: PAID | K29: PERSADA | L29: MONTHLY | N29: 2026
C30: PS-046-00 | D30: {=_xlfn.XLOOKUP(Tabel2[[#This Row],[KODE PROJECT]], _xlfn.VSTACK('KODE PROJECT BARU'!$B$5:$B$98, 'KODE PROJECT BARU'!$C$5:$C$98), _xlfn.VSTACK('KODE PROJECT BARU'!$E$5:$E$98, 'KODE PROJECT BARU'!$E$5:$E$98), "Tidak Ditemukan", 0, 1)} -> #NAME? | E30: UPAH | F30: DMO | G30: Ulfa | H30: FEBRUARI | I30: 7607974 | J30: PAID | K30: PERSADA | L30: MONTHLY | N30: 2026
C31: PS-046-00 | D31: {=_xlfn.XLOOKUP(Tabel2[[#This Row],[KODE PROJECT]], _xlfn.VSTACK('KODE PROJECT BARU'!$B$5:$B$98, 'KODE PROJECT BARU'!$C$5:$C$98), _xlfn.VSTACK('KODE PROJECT BARU'!$E$5:$E$98, 'KODE PROJECT BARU'!$E$5:$E$98), "Tidak Ditemukan", 0, 1)} -> #NAME? | E31: UPAH | F31: DMO | G31: Ulfa | H31: MARET | I31: 7607974 | J31: PAID | K31: PERSADA | L31: MONTHLY | N31: 2026
C32: PS-046-00 | D32: {=_xlfn.XLOOKUP(Tabel2[[#This Row],[KODE PROJECT]], _xlfn.VSTACK('KODE PROJECT BARU'!$B$5:$B$98, 'KODE PROJECT BARU'!$C$5:$C$98), _xlfn.VSTACK('KODE PROJECT BARU'!$E$5:$E$98, 'KODE PROJECT BARU'!$E$5:$E$98), "Tidak Ditemukan", 0, 1)} -> #NAME? | E32: THRK | F32: DMO | G32: Ulfa | H32: MARET | I32: 5870350 | J32: PAID | K32: PERSADA | L32: OTC | N32: 2026
C33: PS-004-00 | D33: {=_xlfn.XLOOKUP(Tabel2[[#This Row],[KODE PROJECT]], _xlfn.VSTACK('KODE PROJECT BARU'!$B$5:$B$98, 'KODE PROJECT BARU'!$C$5:$C$98), _xlfn.VSTACK('KODE PROJECT BARU'!$E$5:$E$98, 'KODE PROJECT BARU'!$E$5:$E$98), "Tidak Ditemukan", 0, 1)} -> #NAME? | E33: UPAH | F33: DMO | G33: Ulfa | H33: JANUARI | I33: 618542477 | J33: PAID | K33: PERSADA | L33: MONTHLY | N33: 2026
C34: PS-004-00 | D34: {=_xlfn.XLOOKUP(Tabel2[[#This Row],[KODE PROJECT]], _xlfn.VSTACK('KODE PROJECT BARU'!$B$5:$B$98, 'KODE PROJECT BARU'!$C$5:$C$98), _xlfn.VSTACK('KODE PROJECT BARU'!$E$5:$E$98, 'KODE PROJECT BARU'!$E$5:$E$98), "Tidak Ditemukan", 0, 1)} -> #NAME? | E34: UPAH | F34: DMO | G34: Ulfa | H34: FEBRUARI | I34: 630360579 | J34: PAID | K34: PERSADA | L34: MONTHLY | N34: 2026
C35: PS-004-00 | D35: {=_xlfn.XLOOKUP(Tabel2[[#This Row],[KODE PROJECT]], _xlfn.VSTACK('KODE PROJECT BARU'!$B$5:$B$98, 'KODE PROJECT BARU'!$C$5:$C$98), _xlfn.VSTACK('KODE PROJECT BARU'!$E$5:$E$98, 'KODE PROJECT BARU'!$E$5:$E$98), "Tidak Ditemukan", 0, 1)} -> #NAME? | E35: UPAH | F35: DMO | G35: Ulfa | H35: MARET | I35: 631560786 | J35: PAID | K35: PERSADA | L35: MONTHLY | N35: 2026
C36: PS-004-00 | D36: {=_xlfn.XLOOKUP(Tabel2[[#This Row],[KODE PROJECT]], _xlfn.VSTACK('KODE PROJECT BARU'!$B$5:$B$98, 'KODE PROJECT BARU'!$C$5:$C$98), _xlfn.VSTACK('KODE PROJECT BARU'!$E$5:$E$98, 'KODE PROJECT BARU'!$E$5:$E$98), "Tidak Ditemukan", 0, 1)} -> #NAME? | E36: TUNJANGAN TIDAK TETAP | F36: DMO | G36: Ulfa | H36: JANUARI | I36: 11273150 | J36: PAID | K36: PERSADA | L36: OTC | N36: 2026
... C50: PS-008-00 | D50: {=_xlfn.XLOOKUP(Tabel2[[#This Row],[KODE PROJECT]], _xlfn.VSTACK('KODE PROJECT BARU'!$B$5:$B$98, 'KODE PROJECT BARU'!$C$5:$C$98), _xlfn.VSTACK('KODE PROJECT BARU'!$E$5:$E$98, 'KODE PROJECT BARU'!$E$5:$E$98), "Tidak Ditemukan", 0, 1)} -> #NAME? | E50: THRK | F50: DMO | G50: Ulfa | H50: MARET | I50: 6337046 | J50: PAID | K50: PERSADA | L50: OTC | N50: 2026
C51: PS-023-00 | D51: {=_xlfn.XLOOKUP(Tabel2[[#This Row],[KODE PROJECT]], _xlfn.VSTACK('KODE PROJECT BARU'!$B$5:$B$98, 'KODE PROJECT BARU'!$C$5:$C$98), _xlfn.VSTACK('KODE PROJECT BARU'!$E$5:$E$98, 'KODE PROJECT BARU'!$E$5:$E$98), "Tidak Ditemukan", 0, 1)} -> #NAME? | E51: UPAH | F51: DMO | G51: Ulfa | H51: JANUARI | I51: =652725791-4995298 -> 647730493 | J51: PAID | K51: PERSADA | L51: MONTHLY | N51: 2026
C52: PS-023-00 | D52: {=_xlfn.XLOOKUP(Tabel2[[#This Row],[KODE PROJECT]], _xlfn.VSTACK('KODE PROJECT BARU'!$B$5:$B$98, 'KODE PROJECT BARU'!$C$5:$C$98), _xlfn.VSTACK('KODE PROJECT BARU'!$E$5:$E$98, 'KODE PROJECT BARU'!$E$5:$E$98), "Tidak Ditemukan", 0, 1)} -> #NAME? | E52: UPAH | F52: DMO | G52: Ulfa | H52: FEBRUARI | I52: =652725791-7936357 -> 644789434 | J52: PAID | K52: PERSADA | L52: MONTHLY | N52: 2026
C53: PS-023-00 | D53: {=_xlfn.XLOOKUP(Tabel2[[#This Row],[KODE PROJECT]], _xlfn.VSTACK('KODE PROJECT BARU'!$B$5:$B$98, 'KODE PROJECT BARU'!$C$5:$C$98), _xlfn.VSTACK('KODE PROJECT BARU'!$E$5:$E$98, 'KODE PROJECT BARU'!$E$5:$E$98), "Tidak Ditemukan", 0, 1)} -> #NAME? | E53: UPAH | F53: DMO | G53: Ulfa | H53: MARET | I53: =652725791-26885241 -> 625840550 | J53: PAID | K53: PERSADA | L53: MONTHLY | N53: 2026
C54: PS-023-00 | D54: {=_xlfn.XLOOKUP(Tabel2[[#This Row],[KODE PROJECT]], _xlfn.VSTACK('KODE PROJECT BARU'!$B$5:$B$98, 'KODE PROJECT BARU'!$C$5:$C$98), _xlfn.VSTACK('KODE PROJECT BARU'!$E$5:$E$98, 'KODE PROJECT BARU'!$E$5:$E$98), "Tidak Ditemukan", 0, 1)} -> #NAME? | E54: PARKIR | F54: DMO | G54: Ulfa | H54: JANUARI | I54: 937178 | J54: PAID | K54: PERSADA | L54: OTC | N54: 2026
C55: PS-023-00 | D55: {=_xlfn.XLOOKUP(Tabel2[[#This Row],[KODE PROJECT]], _xlfn.VSTACK('KODE PROJECT BARU'!$B$5:$B$98, 'KODE PROJECT BARU'!$C$5:$C$98), _xlfn.VSTACK('KODE PROJECT BARU'!$E$5:$E$98, 'KODE PROJECT BARU'!$E$5:$E$98), "Tidak Ditemukan", 0, 1)} -> #NAME? | E55: PARKIR | F55: DMO | G55: Ulfa | H55: FEBRUARI | I55: 822888 | J55: PAID | K55: PERSADA | L55: OTC | N55: 2026
...

Sheet Lembar1
B2: Project implementasi, perlu direview
B3: Project_ID | C3: Year | D3: Status | E3: Service Manager | F3: Project_client | G3: Project clasification | H3: Project Name | I3: Contract Number | J3: Category Contract | L3: Date of Contract | M3: Start Date | N3: End Date | O3: Project_Value | P3: Costbased | Q3: Actual Cost konfirmasi | R3: Actual cost (admin) | S3: Persentase | T3: Amandemen | U3: TKDN | V3: Description
